<?xml version="1.0" encoding="UTF-8"?>
<robot generator="Robot 3.2.2 (Python 3.6.5 on win32)" generated="20210415 16:15:07.470" rpa="false">
<suite id="s1" name="Test" source="C:\Users\lab1321\Desktop\RED_0.9.4.20200428111032-win32.win32.x86_64\workspace\test">
<suite id="s1-s1" name="Test" source="C:\Users\lab1321\Desktop\RED_0.9.4.20200428111032-win32.win32.x86_64\workspace\test\test.robot">
<test id="s1-s1-t1" name="Test">
<kw name="setup and open android phone1">
<msg timestamp="20210415 16:15:08.366" level="TRACE">Arguments: [  ]</msg>
<kw name="Open Application" library="AppiumLibrary">
<doc>Opens a new application to given Appium server.
Capabilities of appium server, Android and iOS,
Please check https://github.com/appium/appium/blob/master/docs/en/writing-running-appium/server-args.md
| *Option*            | *Man.* | *Description*     |
| remote_url          | Yes    | Appium server url |
| alias               | no     | alias             |</doc>
<arguments>
<arg>remote_url=${APPIUM_SERVER1}</arg>
<arg>platformName=android</arg>
<arg>platformVersion=9.0</arg>
<arg>deviceName=emulator-5554</arg>
<arg>automationName=uiautomator2</arg>
<arg>appPackage=com.zotiger.accountbook</arg>
<arg>newCommaUndTimeout=2500</arg>
<arg>appActivity=com.zotiger.accountbook.MainActivity</arg>
</arguments>
<assign>
<var>${androiddriver1}</var>
</assign>
<msg timestamp="20210415 16:15:08.367" level="TRACE">Arguments: [ remote_url='http://127.0.0.1:4723/wd/hub' | platformName='android' | platformVersion='9.0' | deviceName='emulator-5554' | automationName='uiautomator2' | appPackage='com.zotiger.accountbook' | newCommaUndTimeout='2500' | appActivity='com.zotiger.accountbook.MainActivity' ]</msg>
<msg timestamp="20210415 16:15:08.390" level="DEBUG">POST http://127.0.0.1:4723/wd/hub/session {"capabilities": {"firstMatch": [{"platformName": "android", "appium:platformVersion": "9.0", "appium:deviceName": "emulator-5554", "appium:automationName": "uiautomator2", "appium:appPackage": "com.zotiger.accountbook", "appium:newCommaUndTimeout": "2500", "appium:appActivity": "com.zotiger.accountbook.MainActivity"}]}, "desiredCapabilities": {"platformName": "android", "platformVersion": "9.0", "deviceName": "emulator-5554", "automationName": "uiautomator2", "appPackage": "com.zotiger.accountbook", "newCommaUndTimeout": "2500", "appActivity": "com.zotiger.accountbook.MainActivity"}}</msg>
<msg timestamp="20210415 16:15:08.392" level="DEBUG">Starting new HTTP connection (1): 127.0.0.1:4723</msg>
<msg timestamp="20210415 16:15:10.936" level="DEBUG">http://127.0.0.1:4723 "POST /wd/hub/session HTTP/1.1" 500 935</msg>
<msg timestamp="20210415 16:15:10.937" level="DEBUG">Finished Request</msg>
<kw name="Capture Page Screenshot" library="AppiumLibrary">
<doc>Takes a screenshot of the current page and embeds it into the log.</doc>
<msg timestamp="20210415 16:15:10.941" level="TRACE">Arguments: [  ]</msg>
<msg timestamp="20210415 16:15:10.954" level="FAIL">No application is open</msg>
<msg timestamp="20210415 16:15:10.954" level="DEBUG">Traceback (most recent call last):
  File "&lt;decorator-gen-32&gt;", line 2, in capture_page_screenshot
  File "C:\Program Files\Python36\Lib\site-packages\AppiumLibrary\keywords\keywordgroup.py", line 21, in _run_on_failure_decorator
    raise err
  File "C:\Program Files\Python36\Lib\site-packages\AppiumLibrary\keywords\keywordgroup.py", line 16, in _run_on_failure_decorator
    return method(*args, **kwargs)
  File "C:\Program Files\Python36\Lib\site-packages\AppiumLibrary\keywords\_screenshot.py", line 31, in capture_page_screenshot
    if hasattr(self._current_application(), 'get_screenshot_as_file'):
  File "C:\Program Files\Python36\Lib\site-packages\AppiumLibrary\keywords\_applicationmanagement.py", line 349, in _current_application
    raise RuntimeError('No application is open')</msg>
<status status="FAIL" starttime="20210415 16:15:10.938" endtime="20210415 16:15:10.954"></status>
</kw>
<msg timestamp="20210415 16:15:10.956" level="WARN">Keyword 'Capture Page Screenshot' could not be run on failure: No application is open</msg>
<msg timestamp="20210415 16:15:10.976" level="FAIL">WebDriverException: Message: An unknown server-side error occurred while processing the command. Original error: Neither ANDROID_HOME nor ANDROID_SDK_ROOT environment variable was exported. Read https://developer.android.com/studio/command-line/variables for more details
</msg>
<msg timestamp="20210415 16:15:10.976" level="DEBUG">Traceback (most recent call last):
  File "&lt;decorator-gen-35&gt;", line 2, in open_application
  File "C:\Program Files\Python36\Lib\site-packages\AppiumLibrary\keywords\keywordgroup.py", line 21, in _run_on_failure_decorator
    raise err
  File "C:\Program Files\Python36\Lib\site-packages\AppiumLibrary\keywords\keywordgroup.py", line 16, in _run_on_failure_decorator
    return method(*args, **kwargs)
  File "C:\Program Files\Python36\Lib\site-packages\AppiumLibrary\keywords\_applicationmanagement.py", line 52, in open_application
    application = webdriver.Remote(str(remote_url), desired_caps)
  File "C:\Program Files\Python36\Lib\site-packages\appium\webdriver\webdriver.py", line 156, in __init__
    AppiumConnection(command_executor, keep_alive=keep_alive), desired_capabilities, browser_profile, proxy
  File "C:\Program Files\Python36\Lib\site-packages\selenium\webdriver\remote\webdriver.py", line 157, in __init__
    self.start_session(capabilities, browser_profile)
  File "C:\Program Files\Python36\Lib\site-packages\appium\webdriver\webdriver.py", line 225, in start_session
    response = self.execute(RemoteCommand.NEW_SESSION, parameters)
  File "C:\Program Files\Python36\Lib\site-packages\selenium\webdriver\remote\webdriver.py", line 321, in execute
    self.error_handler.check_response(response)
  File "C:\Program Files\Python36\Lib\site-packages\selenium\webdriver\remote\errorhandler.py", line 242, in check_response
    raise exception_class(message, screen, stacktrace)</msg>
<status status="FAIL" starttime="20210415 16:15:08.367" endtime="20210415 16:15:10.976"></status>
</kw>
<status status="FAIL" starttime="20210415 16:15:08.366" endtime="20210415 16:15:10.977"></status>
</kw>
<status status="FAIL" starttime="20210415 16:15:08.365" endtime="20210415 16:15:10.977" critical="yes">WebDriverException: Message: An unknown server-side error occurred while processing the command. Original error: Neither ANDROID_HOME nor ANDROID_SDK_ROOT environment variable was exported. Read https://developer.android.com/studio/command-line/variables for more details
</status>
</test>
<doc>This script starts apps on two phones</doc>
<status status="FAIL" starttime="20210415 16:15:07.606" endtime="20210415 16:15:10.978"></status>
</suite>
<status status="FAIL" starttime="20210415 16:15:07.578" endtime="20210415 16:15:10.981"></status>
</suite>
<statistics>
<total>
<stat pass="0" fail="1">Critical Tests</stat>
<stat pass="0" fail="1">All Tests</stat>
</total>
<tag>
</tag>
<suite>
<stat pass="0" fail="1" id="s1" name="Test">Test</stat>
<stat pass="0" fail="1" id="s1-s1" name="Test">Test.Test</stat>
</suite>
</statistics>
<errors>
<msg timestamp="20210415 16:15:07.558" level="ERROR">Taking listener './dctlib/listeners/no_rush.py' into use failed: Importing listener 'dctlib\listeners\no_rush.py' failed: ModuleNotFoundError: No module named 'dctlib\\listeners\\no_rush'
Traceback (most recent call last):
  None
PYTHONPATH:
  C:\Program Files\Python36\Lib\site-packages
  C:\Users\lab1321\Desktop\RED_0.9.4.20200428111032-win32.win32.x86_64\workspace\test
  C:\Program Files\Python36\python36.zip
  C:\Program Files\Python36\DLLs
  C:\Program Files\Python36\lib
  C:\Program Files\Python36
  C:\Program Files\Python36\lib\site-packages
  C:\Program Files\Python36\lib\site-packages\win32
  C:\Program Files\Python36\lib\site-packages\win32\lib
  C:\Program Files\Python36\lib\site-packages\Pythonwin</msg>
<msg timestamp="20210415 16:15:07.561" level="ERROR">Taking listener './dctlib/listeners/ConsoleAndNetworkLog.py' into use failed: Importing listener 'dctlib\listeners\ConsoleAndNetworkLog.py' failed: ModuleNotFoundError: No module named 'dctlib\\listeners\\ConsoleAndNetworkLog'
Traceback (most recent call last):
  None
PYTHONPATH:
  C:\Program Files\Python36\Lib\site-packages
  C:\Users\lab1321\Desktop\RED_0.9.4.20200428111032-win32.win32.x86_64\workspace\test
  C:\Program Files\Python36\python36.zip
  C:\Program Files\Python36\DLLs
  C:\Program Files\Python36\lib
  C:\Program Files\Python36
  C:\Program Files\Python36\lib\site-packages
  C:\Program Files\Python36\lib\site-packages\win32
  C:\Program Files\Python36\lib\site-packages\win32\lib
  C:\Program Files\Python36\lib\site-packages\Pythonwin</msg>
<msg timestamp="20210415 16:15:07.564" level="ERROR">Taking listener './dctlib/listeners/double_click_retry.py' into use failed: Importing listener 'dctlib\listeners\double_click_retry.py' failed: ModuleNotFoundError: No module named 'dctlib\\listeners\\double_click_retry'
Traceback (most recent call last):
  None
PYTHONPATH:
  C:\Program Files\Python36\Lib\site-packages
  C:\Users\lab1321\Desktop\RED_0.9.4.20200428111032-win32.win32.x86_64\workspace\test
  C:\Program Files\Python36\python36.zip
  C:\Program Files\Python36\DLLs
  C:\Program Files\Python36\lib
  C:\Program Files\Python36
  C:\Program Files\Python36\lib\site-packages
  C:\Program Files\Python36\lib\site-packages\win32
  C:\Program Files\Python36\lib\site-packages\win32\lib
  C:\Program Files\Python36\lib\site-packages\Pythonwin</msg>
<msg timestamp="20210415 16:15:07.568" level="ERROR">Taking listener './dctlib/listeners/close_browser_listener.py' into use failed: Importing listener 'dctlib\listeners\close_browser_listener.py' failed: ModuleNotFoundError: No module named 'dctlib\\listeners\\close_browser_listener'
Traceback (most recent call last):
  None
PYTHONPATH:
  C:\Program Files\Python36\Lib\site-packages
  C:\Users\lab1321\Desktop\RED_0.9.4.20200428111032-win32.win32.x86_64\workspace\test
  C:\Program Files\Python36\python36.zip
  C:\Program Files\Python36\DLLs
  C:\Program Files\Python36\lib
  C:\Program Files\Python36
  C:\Program Files\Python36\lib\site-packages
  C:\Program Files\Python36\lib\site-packages\win32
  C:\Program Files\Python36\lib\site-packages\win32\lib
  C:\Program Files\Python36\lib\site-packages\Pythonwin</msg>
<msg timestamp="20210415 16:15:07.572" level="ERROR">Taking listener './dctlib/listeners/mouseDown.py' into use failed: Importing listener 'dctlib\listeners\mouseDown.py' failed: ModuleNotFoundError: No module named 'dctlib\\listeners\\mouseDown'
Traceback (most recent call last):
  None
PYTHONPATH:
  C:\Program Files\Python36\Lib\site-packages
  C:\Users\lab1321\Desktop\RED_0.9.4.20200428111032-win32.win32.x86_64\workspace\test
  C:\Program Files\Python36\python36.zip
  C:\Program Files\Python36\DLLs
  C:\Program Files\Python36\lib
  C:\Program Files\Python36
  C:\Program Files\Python36\lib\site-packages
  C:\Program Files\Python36\lib\site-packages\win32
  C:\Program Files\Python36\lib\site-packages\win32\lib
  C:\Program Files\Python36\lib\site-packages\Pythonwin</msg>
<msg timestamp="20210415 16:15:10.956" level="WARN">Keyword 'Capture Page Screenshot' could not be run on failure: No application is open</msg>
</errors>
</robot>
